<?xml version="1.0" ?><!-- =================================================================================== --><!-- |    This document was autogenerated by xacro from /home/pac48/unity_ws/install/pioneer_description/share/pioneer_description/urdf/pioneer3dx.xacro | --><!-- |    EDITING THIS FILE BY HAND IS NOT RECOMMENDED                                 | --><!-- =================================================================================== --><!-- Adapted from the p2os package, see http://wiki.ros.org/p2os --><!-- Git repository at https://github.com/allenh1/p2os -->
<robot name="pioneer3dx" xmlns:controller="http://playerstage.sourceforge.net/gazebo/xmlschema/#controller"
       xmlns:interface="http://playerstage.sourceforge.net/gazebo/xmlschema/#interface"
       xmlns:sensor="http://playerstage.sourceforge.net/gazebo/xmlschema/#sensor">  <!--<include filename="$(find pioneer_description)/defs/materials.xacro"/>-->
    <material
            name="ChassisRed">
        <color rgba="0.851 0.0 0.0 1.0"/>
    </material>
    <material name="SonarYellow">
        <color
                rgba="0.715 0.583 0.210 1.0"/>
    </material>
    <material name="WheelBlack">
        <color
                rgba="0.117 0.117 0.117 1.0"/>
    </material>
    <material name="HubcapYellow">
        <color
                rgba="1.0 0.811 0.151 1.0"/>
    </material>
    <material name="TopBlack">
        <color
                rgba="0.038 0.038 0.038 1.0"/>
    </material>
    <material name="swivel">
        <color
                rgba="0.5 0.5 0.5 1"/>
    </material>
    <material name="HubcapGrey">
        <color
                rgba="0.4 0.4 0.4 1"/>
    </material>
    <material name="CameraGreen">
        <color
                rgba="0.0 0.8 0.0 1.0"/>
    </material>  <!-- ros_control plugin -->  <!--<gazebo>    <plugin name="differential_drive_controller" filename="libDiffDrivePlugin.so">      <updateRate>100.0</updateRate>      <robotNamespace>pioneer</robotNamespace>      <left_joint>base_left_wheel_joint</left_joint>      <right_joint>base_right_wheel_joint</right_joint>      <torque>200</torque>      <topicName>cmd_vel</topicName>    </plugin>  </gazebo>-->  <!-- START: Not sure if I need this, may allow for rosservice calls to gazebo joint manager -->
    <gazebo>
        <plugin filename="libgazebo_ros_control.so" name="gazebo_ros_control">
            <robotSimType>
                gazebo_ros_control/DefaultRobotHWSim
            </robotSimType>
            <legacyModeNS>true</legacyModeNS>
        </plugin>
    </gazebo>  <!-- END: Not sure if I need this -->
    <gazebo>
        <plugin filename=
                        "libgazebo_ros_diff_drive.so" name="differential_drive_controller">
            <alwaysOn>true</alwaysOn>
            <updateRate>100</updateRate>
            <leftJoint>base_left_wheel_joint</leftJoint>
            <rightJoint>base_right_wheel_joint</rightJoint>
            <torque>5</torque>
            <wheelSeparation>0.39</wheelSeparation>
            <wheelDiameter>0.15</wheelDiameter>
            <commandTopic>pioneer/cmd_vel</commandTopic>
            <odometryTopic>odom</odometryTopic>
            <odometryFrame>odom</odometryFrame>
            <robotBaseFrame>base_link</robotBaseFrame>
            <publishWheelTF>true</publishWheelTF>
            <publishWheelJointState>true</publishWheelJointState>
            <wheelAcceleration>0</wheelAcceleration>
            <wheelTorque>5</wheelTorque>
            <rosDebugLevel>na</rosDebugLevel>
            <legacyMode>true</legacyMode>
        </plugin>
    </gazebo>  <!--<gazebo>    <plugin name="skid_steer_drive_controller" filename="libgazebo_ros_skid_steer_drive.so">      <updateRate>100.0</updateRate>      <robotNamespace>/pioneer</robotNamespace>      <leftFrontJoint>base_left_wheel_joint</leftFrontJoint>      <rightFrontJoint>base_right_wheel_joint</rightFrontJoint>      <leftRearJoint>base_left_wheel_joint</leftRearJoint>      <rightRearJoint>base_right_wheel_joint</rightRearJoint>      <wheelSeparation>0.39</wheelSeparation>      <wheelDiameter>0.15</wheelDiameter>      <robotBaseFrame>base_link</robotBaseFrame>      <torque>200</torque>      <topicName>cmd_vel</topicName>    </plugin>  </gazebo>-->  <!-- Chassis -->
    <gazebo
            reference="chassis">
        <material value="Gazebo/Red"/>
    </gazebo>  <!-- Top -->
    <gazebo
            reference="top_plate">
        <material value="Gazebo/Black"/>
    </gazebo>  <!-- Swivel -->
    <gazebo
            reference="swivel">
        <material value="Gazebo/Grey"/>
    </gazebo>  <!-- Center Wheel + Hubcap -->
    <gazebo
            reference="center_hubcap">
        <material value="Gazebo/Grey"/>
    </gazebo>
    <gazebo
            reference="center_wheel">
        <material value="Gazebo/Black"/>
    </gazebo>
    <gazebo
            reference="left_hub">
        <material value="Gazebo/Yellow"/>
    </gazebo>
    <gazebo
            reference="left_wheel">
        <material value="Gazebo/Black"/>
    </gazebo>
    <gazebo
            reference="right_hub">
        <material value="Gazebo/Yellow"/>
    </gazebo>
    <gazebo
            reference="right_wheel">
        <material value="Gazebo/Black"/>
    </gazebo>  <!-- Front + Back Sonar -->
    <gazebo
            reference="front_sonar">
        <material value="Gazebo/Yellow"/>
    </gazebo>
    <gazebo
            reference="back_sonar">
        <material value="Gazebo/Yellow"/>
    </gazebo>  <!-- camera_link -->
    <gazebo
            reference="camera_link">
        <mu1>0.2</mu1>
        <mu2>0.2</mu2>
        <material
                value="Gazebo/Green"/>
    </gazebo>  <!-- hokuyo -->
    <gazebo reference="laser">
        <sensor
                name="head_hokuyo_sensor" type="ray">
            <pose>0 0 0 0 0 0</pose>
            <visualize>true
            </visualize>
            <update_rate>40</update_rate>
            <ray>
                <scan>
                    <horizontal>
                        <samples>720</samples>
                        <resolution>1</resolution>
                        <min_angle>-3.1415927</min_angle>
                        <max_angle>3.1415927</max_angle>
                    </horizontal>
                </scan>
                <range>
                    <min>0.10</min>
                    <max>30.0</max>
                    <resolution>0.01</resolution>
                </range>
                <noise>
                    <type>gaussian
                    </type>          <!-- Noise parameters based on published spec for Hokuyo laser               achieving "+-30mm" accuracy at range < 10m.  A mean of 0.0m and               stddev of 0.01m will put 99.7% of samples within 0.03m of the true               reading. -->
                    <mean>0.0</mean>
                    <stddev>0.01</stddev>
                </noise>
            </ray>
            <plugin filename="libgazebo_ros_laser.so" name="gazebo_ros_head_hokuyo_controller">
                <topicName>
                    base_scan
                </topicName>
                <frameName>laser</frameName>
            </plugin>
        </sensor>
    </gazebo>  <!-- camera -->
    <gazebo
            reference="camera_link">
        <sensor name="camera" type="camera">
            <update_rate>30.0</update_rate>
            <camera
                    name="head">
                <horizontal_fov>1.3962634</horizontal_fov>
                <image>
                    <width>800</width>
                    <height>800</height>
                    <format>R8G8B8</format>
                </image>
                <clip>
                    <near>0.02</near>
                    <far>300</far>
                </clip>
                <noise
                        type="gaussian">          <!-- Noise is sampled independently per pixel on each frame.                 That pixel's noise value is added to each of its color               channels, which at that point lie in the range [0,1]. -->
                    <mean>
                        0.0
                    </mean>
                    <stddev>0.007</stddev>
                </noise>
            </camera>
            <plugin
                    filename="libgazebo_ros_camera.so" name="camera_controller">
                <alwaysOn>true</alwaysOn>
                <updateRate>
                    0.0
                </updateRate>
                <cameraName>camera</cameraName>
                <imageTopicName>image_raw
                </imageTopicName>
                <cameraInfoTopicName>camera_info</cameraInfoTopicName>
                <frameName>camera_link
                </frameName>
                <hackBaseline>0.07</hackBaseline>
                <distortionK1>0.0</distortionK1>
                <distortionK2>0.0
                </distortionK2>
                <distortionK3>0.0</distortionK3>
                <distortionT1>0.0</distortionT1>
                <distortionT2>
                    0.0
                </distortionT2>
            </plugin>
        </sensor>
    </gazebo>  <!-- Base link to interface with gmapping and move_base -->
    <link
            name="base_link"/>  <!-- Chassis -->
    <joint name="chassis_joint" type="fixed">
        <origin
                rpy="0 0 0" xyz="-0.045 0 0.148"/>
        <parent link="base_link"/>
        <child link="chassis"/>
    </joint>
    <link
            name="chassis">
        <visual name="chassis_visual">
            <origin rpy="0 0 0" xyz="0 0 0"/>
            <geometry
                    name="pioneer_geom">
                <mesh
                        filename="package://pioneer_description/meshes/p3dx_meshes/chassis.obj"/>
            </geometry>
            <material
                    name="ChassisRed"/>
        </visual>
        <collision>
            <origin rpy="0 0 0" xyz="0 0 0"/>
            <geometry>
                <mesh filename=
                              "package://pioneer_description/meshes/p3dx_meshes/chassis.obj"/>        <!--box size="0.43 0.277 0.17"/-->
            </geometry>
        </collision>
        <inertial>
            <mass value="5.67"/>
            <inertia ixx="0.07" ixy="0" ixz="0" iyy="0.08" iyz="0"
                     izz="0.10"/>
        </inertial>
    </link>  <!-- Top -->
    <joint name="base_top_joint" type="fixed">
        <origin
                rpy="0 0 0" xyz="-0.045 0 0.234"/>
        <parent link="base_link"/>
        <child link="top_plate"/>
    </joint>
    <link
            name="top_plate">
        <visual>
            <inertial>
                <mass value="0.01"/>
                <origin xyz="0 0 0"/>
                <inertia ixx="1" ixy="0" ixz="0" iyy="1" iyz="0"
                         izz="1"/>
            </inertial>
            <origin rpy="0 0 0" xyz="0 0 0"/>
            <geometry name="top_geom">
                <mesh filename=
                              "package://pioneer_description/meshes/p3dx_meshes/top.obj"/>
            </geometry>
            <material name="TopBlack"/>
        </visual>
        <collision>
            <origin rpy="0 0 0" xyz="0 0 0"/>
            <geometry>
                <mesh filename=
                              "package://pioneer_description/meshes/p3dx_meshes/top.obj"/>        <!--box size="0.44 0.38 0.005"/-->
            </geometry>
        </collision>
    </link>  <!-- Swivel -->
    <joint name="base_swivel_joint" type="continuous">
        <origin
                rpy="0 0 0" xyz="-0.185 0 0.055"/>
        <axis
                xyz="0 0 1"/>    <!--<anchor xyz="0 0 0"/>  t<limit effort="100" velocity="100" k_velocity="0" />  t<joint_properties damping="0.0" friction="0.0" />-->
        <parent
                link="base_link"/>
        <child link="swivel"/>
    </joint>
    <link name="swivel">
        <inertial>
            <mass value=
                          "0.1"/>
            <origin xyz="0 0 0"/>
            <inertia ixx="0.01" ixy="0" ixz="0" iyy="0.01" iyz="0" izz="0.01"/>
        </inertial>
        <visual name="base_visual">
            <origin rpy="0 0 0" xyz="0 0 0"/>
            <geometry
                    name="pioneer_geom">
                <mesh
                        filename="package://pioneer_description/meshes/p3dx_meshes/swivel.obj"/>
            </geometry>
            <material
                    name="swivel"/>
        </visual>
        <collision>
            <origin rpy="0 0 0" xyz="0 0 0"/>
            <geometry>
                <mesh filename="package://pioneer_description/meshes/p3dx_meshes/swivel.obj"/>
            </geometry>
        </collision>
    </link>  <!-- Center Wheel + Hubcap -->
    <link name="center_hubcap">
        <inertial>
            <mass value=
                          "0.01"/>
            <origin xyz="0 0 0"/>
            <inertia ixx="0.012411765597" ixy="-0.000711733678" ixz="0.00050272983"
                     iyy="0.015218160428" iyz="-0.000004273467" izz="0.011763977943"/>
        </inertial>
        <visual name="base_visual">
            <origin rpy="0 0 0" xyz="0 0 0"/>
            <geometry
                    name="pioneer_geom">
                <mesh
                        filename="package://pioneer_description/meshes/p3dx_meshes/center_hubcap.obj"/>
            </geometry>
            <material
                    name="HubcapGrey"/>
        </visual>
        <collision>
            <origin rpy="0 0 0" xyz="0 0 0"/>
            <geometry>
                <mesh filename="package://pioneer_description/meshes/p3dx_meshes/center_hubcap.obj"/>
            </geometry>
        </collision>
    </link>
    <joint name="swivel_hubcap_joint" type="continuous">
        <origin
                rpy="0 0 0" xyz="-0.026 0 -0.016"/>
        <axis
                xyz="0 1 0"/>    <!--<anchor xyz="0 0 0"/>    <limit effort="1000" velocity="1000" k_velocity="0" />    <joint_properties damping="0.0" friction="0.0" />-->
        <parent
                link="swivel"/>
        <child link="center_wheel"/>
    </joint>
    <link name="center_wheel">
        <inertial>
            <mass
                    value="0.1"/>
            <origin xyz="0 0 0"/>
            <inertia ixx="0.012411765597" ixy="-0.000711733678"
                     ixz="0.00050272983" iyy="0.015218160428" iyz="-0.000004273467" izz="0.011763977943"/>
        </inertial>
        <visual name="base_visual">
            <origin rpy="0 0 0" xyz="0 0 0"/>
            <geometry
                    name="pioneer_geom">
                <mesh
                        filename="package://pioneer_description/meshes/p3dx_meshes/center_wheel.obj"/>
            </geometry>
            <material
                    name="WheelBlack"/>
        </visual>
        <collision>
            <origin rpy="0 0 0" xyz="0 0 0"/>
            <geometry>
                <mesh filename=
                              "package://pioneer_description/meshes/p3dx_meshes/center_wheel.obj"/>        <!--<cylinder radius="0.0375" length="0.03"/>-->
            </geometry>
        </collision>
    </link>
    <joint name="center_wheel_joint" type="fixed">
        <origin
                rpy="0 0 0" xyz="-0.0035 0 -0.001"/>
        <parent link="center_wheel"/>
        <child
                link="center_hubcap"/>
    </joint>  <!-- Left Wheel -->
    <joint
            name="base_left_wheel_joint" type="continuous">
        <origin rpy="0 0 0" xyz="0 0.155 0.093"/>
        <axis
                xyz="0 1 0"/>    <!--<anchor xyz="0 0 0"/>  t<limit effort="1000" velocity="1000" k_velocity="0" />  t<joint_properties damping="0.0" friction="0.0" />-->
        <parent
                link="base_link"/>
        <child link="left_wheel"/>
    </joint>
    <link name="left_wheel">
        <inertial>
            <mass
                    value="0.1"/>
            <origin xyz="0 0 0"/>
            <inertia ixx="0.012411765597" ixy="-0.000711733678"
                     ixz="0.00050272983" iyy="0.015218160428" iyz="-0.000004273467" izz="0.011763977943"/>
        </inertial>
        <visual>
            <origin rpy="0 0 0" xyz="0 0 0"/>
            <geometry>
                <mesh filename="package://pioneer_description/meshes/p3dx_meshes/left_wheel.obj"/>
            </geometry>
            <material name="WheelBlack"/>
        </visual>
        <collision>
            <origin rpy="0 0 0" xyz="0 0 0"/>
            <geometry>
                <mesh filename=
                              "package://pioneer_description/meshes/p3dx_meshes/left_wheel.obj"/>        <!--<cylinder radius="0.092" length="0.04"/>-->
            </geometry>
        </collision>
    </link>
    <joint name="left_wheel_hub_joint" type="fixed">
        <origin
                rpy="0 0 0" xyz="0 0 0"/>
        <parent link="left_wheel"/>
        <child link="left_hub"/>
    </joint>
    <link
            name="left_hub">
        <visual>
            <origin rpy="0 0 0" xyz="0 0 0"/>
            <geometry>
                <mesh filename="package://pioneer_description/meshes/p3dx_meshes/left_hubcap.obj"/>
            </geometry>
            <material name="HubcapYellow"/>
        </visual>
        <collision>
            <origin rpy="0 0 0" xyz="0 0 0"/>
            <geometry>
                <mesh filename="package://pioneer_description/meshes/p3dx_meshes/left_hubcap.obj"/>
            </geometry>
        </collision>
    </link>  <!-- Right Wheel -->
    <joint name="base_right_wheel_joint" type="continuous">
        <origin
                rpy="0 0 0" xyz="0 -0.155 0.093"/>
        <axis
                xyz="0 1 0"/>    <!--<anchor xyz="0 0 0"/>  t<limit effort="1000" velocity="1000" k_velocity="0" />  t<joint_properties damping="0.0" friction="0.0" />-->
        <parent
                link="base_link"/>
        <child link="right_wheel"/>
    </joint>
    <link name="right_wheel">
        <inertial>
            <mass
                    value="0.1"/>
            <origin xyz="0 0 0"/>
            <inertia ixx="0.012411765597" ixy="-0.000711733678"
                     ixz="0.00050272983" iyy="0.015218160428" iyz="-0.000004273467" izz="0.011763977943"/>
        </inertial>
        <visual>
            <origin rpy="0 0 0" xyz="0 0 0"/>
            <geometry>
                <mesh filename="package://pioneer_description/meshes/p3dx_meshes/right_wheel.obj"/>
            </geometry>
            <material name="WheelBlack"/>
        </visual>
        <collision>
            <origin rpy="0 0 0" xyz="0 0 0"/>
            <geometry>
                <mesh filename=
                              "package://pioneer_description/meshes/p3dx_meshes/right_wheel.obj"/>        <!--<cylinder radius="0.092" length="0.04"/>-->
            </geometry>
        </collision>
    </link>
    <joint name="right_wheel_hub_joint" type="fixed">
        <origin
                rpy="0 0 0" xyz="0 0 0"/>
        <parent link="right_wheel"/>
        <child link="right_hub"/>
    </joint>
    <link
            name="right_hub">
        <visual>
            <origin rpy="0 0 0" xyz="0 0 0"/>
            <geometry>
                <mesh filename="package://pioneer_description/meshes/p3dx_meshes/right_hubcap.obj"/>
            </geometry>
            <material name="HubcapYellow"/>
        </visual>
        <collision>
            <origin rpy="0 0 0" xyz="0 0 0"/>
            <geometry>
                <mesh filename="package://pioneer_description/meshes/p3dx_meshes/right_hubcap.obj"/>
            </geometry>
        </collision>
    </link>  <!-- Front + Back Sonar -->
    <link name="front_sonar">
        <inertial>
            <mass value=
                          "0.0001"/>
            <origin xyz="0 0 0"/>
            <inertia ixx="1" ixy="0" ixz="0" iyy="1" iyz="0" izz="1"/>
        </inertial>
        <visual name="base_visual">
            <origin rpy="0 0 0" xyz="0 0 0"/>
            <geometry
                    name="pioneer_geom">
                <mesh
                        filename="package://pioneer_description/meshes/p3dx_meshes/front_sonar.obj"/>
            </geometry>
            <material
                    name="SonarYellow"/>
        </visual>
        <collision>
            <origin rpy="0 0 0" xyz="0 0 0"/>
            <geometry>
                <mesh filename="package://pioneer_description/meshes/p3dx_meshes/front_sonar.obj"/>
            </geometry>
        </collision>
    </link>
    <joint name="base_front_joint" type="fixed">
        <origin
                rpy="0 0 0" xyz="-0.198 0 0.208"/>
        <parent link="base_link"/>
        <child link="front_sonar"/>
    </joint>
    <link
            name="back_sonar">
        <inertial>
            <mass value="0.0001"/>
            <origin xyz="0 0 0"/>
            <inertia ixx="1" ixy="0"
                     ixz="0" iyy="1" iyz="0" izz="1"/>
        </inertial>
        <visual name="back_sonar_vis">
            <origin rpy="0 0 0" xyz="0 0 0"/>
            <geometry
                    name="pioneer_geom">
                <mesh
                        filename="package://pioneer_description/meshes/p3dx_meshes/back_sonar.obj"/>
            </geometry>
            <material
                    name="SonarYellow"/>
        </visual>
        <collision>
            <origin rpy="0 0 0" xyz="0 0 0"/>
            <geometry>
                <mesh filename="package://pioneer_description/meshes/p3dx_meshes/back_sonar.obj"/>
            </geometry>
        </collision>
    </link>
    <joint name="base_back_joint" type="fixed">
        <origin
                rpy="0 0 0" xyz="0.109 0 0.209"/>
        <parent link="base_link"/>
        <child link="back_sonar"/>
    </joint>
    <joint
            name="hokuyo_joint" type="fixed">
        <origin rpy="0 0 0" xyz="0 0 0.085"/>
        <parent
                link="camera_link"/>
        <child link="laser"/>
    </joint>  <!-- Hokuyo Laser -->
    <link name="laser">
        <collision>
            <origin rpy="0 0 0" xyz="0 0 0"/>
            <geometry>
                <mesh filename=
                              "package://pioneer_description/meshes/hokuyo.dae"/>        <!--box size="0.05 0.05 0.071"/-->
            </geometry>
        </collision>
        <visual>
            <origin rpy="0 0 0" xyz="0 0 0"/>
            <geometry>
                <mesh filename="package://pioneer_description/meshes/hokuyo.dae"/>
            </geometry>
        </visual>
        <inertial>
            <mass value="1e-5"/>
            <origin rpy="0 0 0" xyz="0 0 0"/>
            <inertia ixx="1e-6" ixy="0"
                     ixz="0" iyy="1e-6" iyz="0" izz="1e-6"/>
        </inertial>
    </link>
    <joint name="camera_joint" type="fixed">
        <origin
                rpy="0 0 0" xyz="0.17 0 0.0255"/>
        <parent link="top_plate"/>
        <child
                link="camera_link"/>
    </joint>  <!-- Camera -->
    <link name="camera_link">
        <collision>
            <origin rpy="0 0 0"
                    xyz="0 0 0"/>
            <geometry>
                <box size="0.05 0.07 0.10"/>
            </geometry>
        </collision>
        <visual>
            <origin rpy="0 0 0" xyz="0 0 0"/>
            <geometry>
                <box size="0.05 0.07 0.10"/>
            </geometry>
            <material name="CameraGreen"/>
        </visual>
        <inertial>
            <mass value="1e-5"/>
            <origin rpy="0 0 0" xyz="0 0 0"/>
            <inertia ixx="1e-6" ixy="0"
                     ixz="0" iyy="1e-6" iyz="0" izz="1e-6"/>
        </inertial>
    </link>  <!-- START: Not sure if I need this, may allow for rosservice calls to gazebo joint manager -->
    <transmission
            name="tran1">
        <type>transmission_interface/SimpleTransmission</type>
        <joint
                name="base_left_wheel_joint">
            <hardwareInterface>EffortJointInterface
            </hardwareInterface>
        </joint>
        <actuator name="motor1">
            <hardwareInterface>EffortJointInterface
            </hardwareInterface>
            <mechanicalReduction>1</mechanicalReduction>
        </actuator>
    </transmission>
    <transmission
            name="tran2">
        <type>transmission_interface/SimpleTransmission</type>
        <joint
                name="base_right_wheel_joint">
            <hardwareInterface>EffortJointInterface
            </hardwareInterface>
        </joint>
        <actuator name="motor2">
            <hardwareInterface>EffortJointInterface
            </hardwareInterface>
            <mechanicalReduction>1
            </mechanicalReduction>
        </actuator>
    </transmission>  <!-- END: Not sure if I need this -->
</robot>

